[23/Aug/2019 14:16:18] ERROR [storageadmin.middleware:33] could not connect to server: No such file or directory
	Is the server running locally and accepting
	connections on Unix domain socket "/var/run/postgresql/.s.PGSQL.5432"?
Traceback (most recent call last):
  File "/opt/rockstor/eggs/Django-1.8.16-py2.7.egg/django/core/handlers/base.py", line 132, in get_response
    response = wrapped_callback(request, *callback_args, **callback_kwargs)
  File "/opt/rockstor/eggs/Django-1.8.16-py2.7.egg/django/views/decorators/csrf.py", line 58, in wrapped_view
    return view_func(*args, **kwargs)
  File "/opt/rockstor/eggs/Django-1.8.16-py2.7.egg/django/views/generic/base.py", line 71, in view
    return self.dispatch(request, *args, **kwargs)
  File "/opt/rockstor/eggs/djangorestframework-3.1.1-py2.7.egg/rest_framework/views.py", line 452, in dispatch
    response = self.handle_exception(exc)
  File "/opt/rockstor/eggs/djangorestframework-3.1.1-py2.7.egg/rest_framework/views.py", line 440, in dispatch
    self.initial(request, *args, **kwargs)
  File "/opt/rockstor/eggs/djangorestframework-3.1.1-py2.7.egg/rest_framework/views.py", line 354, in initial
    self.perform_authentication(request)
  File "/opt/rockstor/eggs/djangorestframework-3.1.1-py2.7.egg/rest_framework/views.py", line 292, in perform_authentication
    request.user
  File "/opt/rockstor/eggs/djangorestframework-3.1.1-py2.7.egg/rest_framework/request.py", line 491, in __getattribute__
    return super(Request, self).__getattribute__(attr)
  File "/opt/rockstor/eggs/djangorestframework-3.1.1-py2.7.egg/rest_framework/request.py", line 266, in user
    self._authenticate()
  File "/opt/rockstor/eggs/djangorestframework-3.1.1-py2.7.egg/rest_framework/request.py", line 454, in _authenticate
    user_auth_tuple = authenticator.authenticate(self)
  File "/opt/rockstor/src/rockstor/rest_framework_custom/oauth_wrapper.py", line 29, in authenticate
    creds = super(RockstorOAuth2Authentication, self).authenticate(request)
  File "/opt/rockstor/eggs/django_oauth_toolkit-0.9.0-py2.7.egg/oauth2_provider/ext/rest_framework/authentication.py", line 18, in authenticate
    valid, r = oauthlib_core.verify_request(request, scopes=[])
  File "/opt/rockstor/eggs/django_oauth_toolkit-0.9.0-py2.7.egg/oauth2_provider/oauth2_backends.py", line 155, in verify_request
    valid, r = self.server.verify_request(uri, http_method, body, headers, scopes=scopes)
  File "/opt/rockstor/eggs/oauthlib-1.0.1-py2.7.egg/oauthlib/oauth2/rfc6749/endpoints/base.py", line 64, in wrapper
    return f(endpoint, uri, *args, **kwargs)
  File "/opt/rockstor/eggs/oauthlib-1.0.1-py2.7.egg/oauthlib/oauth2/rfc6749/endpoints/resource.py", line 75, in verify_request
    return token_type_handler.validate_request(request), request
  File "/opt/rockstor/eggs/oauthlib-1.0.1-py2.7.egg/oauthlib/oauth2/rfc6749/tokens.py", line 286, in validate_request
    token, request.scopes, request)
  File "/opt/rockstor/eggs/django_oauth_toolkit-0.9.0-py2.7.egg/oauth2_provider/oauth2_validators.py", line 224, in validate_bearer_token
    token=token)
  File "/opt/rockstor/eggs/Django-1.8.16-py2.7.egg/django/db/models/query.py", line 328, in get
    num = len(clone)
  File "/opt/rockstor/eggs/Django-1.8.16-py2.7.egg/django/db/models/query.py", line 144, in __len__
    self._fetch_all()
  File "/opt/rockstor/eggs/Django-1.8.16-py2.7.egg/django/db/models/query.py", line 965, in _fetch_all
    self._result_cache = list(self.iterator())
  File "/opt/rockstor/eggs/Django-1.8.16-py2.7.egg/django/db/models/query.py", line 238, in iterator
    results = compiler.execute_sql()
  File "/opt/rockstor/eggs/Django-1.8.16-py2.7.egg/django/db/models/sql/compiler.py", line 838, in execute_sql
    cursor = self.connection.cursor()
  File "/opt/rockstor/eggs/Django-1.8.16-py2.7.egg/django/db/backends/base/base.py", line 162, in cursor
    cursor = self.make_debug_cursor(self._cursor())
  File "/opt/rockstor/eggs/Django-1.8.16-py2.7.egg/django/db/backends/base/base.py", line 135, in _cursor
    self.ensure_connection()
  File "/opt/rockstor/eggs/Django-1.8.16-py2.7.egg/django/db/backends/base/base.py", line 130, in ensure_connection
    self.connect()
  File "/opt/rockstor/eggs/Django-1.8.16-py2.7.egg/django/db/utils.py", line 98, in __exit__
    six.reraise(dj_exc_type, dj_exc_value, traceback)
  File "/opt/rockstor/eggs/Django-1.8.16-py2.7.egg/django/db/backends/base/base.py", line 130, in ensure_connection
    self.connect()
  File "/opt/rockstor/eggs/Django-1.8.16-py2.7.egg/django/db/backends/base/base.py", line 119, in connect
    self.connection = self.get_new_connection(conn_params)
  File "/opt/rockstor/eggs/Django-1.8.16-py2.7.egg/django/db/backends/postgresql_psycopg2/base.py", line 176, in get_new_connection
    connection = Database.connect(**conn_params)
  File "/usr/lib64/python2.7/site-packages/psycopg2/__init__.py", line 126, in connect
    conn = _connect(dsn, connection_factory=connection_factory, **kwasync)
OperationalError: could not connect to server: No such file or directory
	Is the server running locally and accepting
	connections on Unix domain socket "/var/run/postgresql/.s.PGSQL.5432"?

[23/Aug/2019 14:17:18] ERROR [storageadmin.middleware:32] Exception occurred while processing a request. Path: /api/disks/scan method: POST
[23/Aug/2019 14:17:18] ERROR [storageadmin.middleware:33] could not connect to server: No such file or directory
	Is the server running locally and accepting
	connections on Unix domain socket "/var/run/postgresql/.s.PGSQL.5432"?
Traceback (most recent call last):
  File "/opt/rockstor/eggs/Django-1.8.16-py2.7.egg/django/core/handlers/base.py", line 132, in get_response
    response = wrapped_callback(request, *callback_args, **callback_kwargs)
  File "/opt/rockstor/eggs/Django-1.8.16-py2.7.egg/django/views/decorators/csrf.py", line 58, in wrapped_view
    return view_func(*args, **kwargs)
  File "/opt/rockstor/eggs/Django-1.8.16-py2.7.egg/django/views/generic/base.py", line 71, in view
    return self.dispatch(request, *args, **kwargs)
  File "/opt/rockstor/eggs/djangorestframework-3.1.1-py2.7.egg/rest_framework/views.py", line 452, in dispatch
    response = self.handle_exception(exc)
  File "/opt/rockstor/eggs/djangorestframework-3.1.1-py2.7.egg/rest_framework/views.py", line 440, in dispatch
    self.initial(request, *args, **kwargs)
  File "/opt/rockstor/eggs/djangorestframework-3.1.1-py2.7.egg/rest_framework/views.py", line 354, in initial
    self.perform_authentication(request)
  File "/opt/rockstor/eggs/djangorestframework-3.1.1-py2.7.egg/rest_framework/views.py", line 292, in perform_authentication
    request.user
  File "/opt/rockstor/eggs/djangorestframework-3.1.1-py2.7.egg/rest_framework/request.py", line 491, in __getattribute__
    return super(Request, self).__getattribute__(attr)
  File "/opt/rockstor/eggs/djangorestframework-3.1.1-py2.7.egg/rest_framework/request.py", line 266, in user
    self._authenticate()
  File "/opt/rockstor/eggs/djangorestframework-3.1.1-py2.7.egg/rest_framework/request.py", line 454, in _authenticate
    user_auth_tuple = authenticator.authenticate(self)
  File "/opt/rockstor/src/rockstor/rest_framework_custom/oauth_wrapper.py", line 29, in authenticate
    creds = super(RockstorOAuth2Authentication, self).authenticate(request)
  File "/opt/rockstor/eggs/django_oauth_toolkit-0.9.0-py2.7.egg/oauth2_provider/ext/rest_framework/authentication.py", line 18, in authenticate
    valid, r = oauthlib_core.verify_request(request, scopes=[])
  File "/opt/rockstor/eggs/django_oauth_toolkit-0.9.0-py2.7.egg/oauth2_provider/oauth2_backends.py", line 155, in verify_request
    valid, r = self.server.verify_request(uri, http_method, body, headers, scopes=scopes)
  File "/opt/rockstor/eggs/oauthlib-1.0.1-py2.7.egg/oauthlib/oauth2/rfc6749/endpoints/base.py", line 64, in wrapper
    return f(endpoint, uri, *args, **kwargs)
  File "/opt/rockstor/eggs/oauthlib-1.0.1-py2.7.egg/oauthlib/oauth2/rfc6749/endpoints/resource.py", line 75, in verify_request
    return token_type_handler.validate_request(request), request
  File "/opt/rockstor/eggs/oauthlib-1.0.1-py2.7.egg/oauthlib/oauth2/rfc6749/tokens.py", line 286, in validate_request
    token, request.scopes, request)
  File "/opt/rockstor/eggs/django_oauth_toolkit-0.9.0-py2.7.egg/oauth2_provider/oauth2_validators.py", line 224, in validate_bearer_token
    token=token)
  File "/opt/rockstor/eggs/Django-1.8.16-py2.7.egg/django/db/models/query.py", line 328, in get
    num = len(clone)
  File "/opt/rockstor/eggs/Django-1.8.16-py2.7.egg/django/db/models/query.py", line 144, in __len__
    self._fetch_all()
  File "/opt/rockstor/eggs/Django-1.8.16-py2.7.egg/django/db/models/query.py", line 965, in _fetch_all
    self._result_cache = list(self.iterator())
  File "/opt/rockstor/eggs/Django-1.8.16-py2.7.egg/django/db/models/query.py", line 238, in iterator
    results = compiler.execute_sql()
  File "/opt/rockstor/eggs/Django-1.8.16-py2.7.egg/django/db/models/sql/compiler.py", line 838, in execute_sql
    cursor = self.connection.cursor()
  File "/opt/rockstor/eggs/Django-1.8.16-py2.7.egg/django/db/backends/base/base.py", line 162, in cursor
    cursor = self.make_debug_cursor(self._cursor())
  File "/opt/rockstor/eggs/Django-1.8.16-py2.7.egg/django/db/backends/base/base.py", line 135, in _cursor
    self.ensure_connection()
  File "/opt/rockstor/eggs/Django-1.8.16-py2.7.egg/django/db/backends/base/base.py", line 130, in ensure_connection
    self.connect()
  File "/opt/rockstor/eggs/Django-1.8.16-py2.7.egg/django/db/utils.py", line 98, in __exit__
    six.reraise(dj_exc_type, dj_exc_value, traceback)
  File "/opt/rockstor/eggs/Django-1.8.16-py2.7.egg/django/db/backends/base/base.py", line 130, in ensure_connection
    self.connect()
  File "/opt/rockstor/eggs/Django-1.8.16-py2.7.egg/django/db/backends/base/base.py", line 119, in connect
    self.connection = self.get_new_connection(conn_params)
  File "/opt/rockstor/eggs/Django-1.8.16-py2.7.egg/django/db/backends/postgresql_psycopg2/base.py", line 176, in get_new_connection
    connection = Database.connect(**conn_params)
  File "/usr/lib64/python2.7/site-packages/psycopg2/__init__.py", line 126, in connect
    conn = _connect(dsn, connection_factory=connection_factory, **kwasync)
OperationalError: could not connect to server: No such file or directory
	Is the server running locally and accepting
	connections on Unix domain socket "/var/run/postgresql/.s.PGSQL.5432"?

[23/Aug/2019 14:17:18] ERROR [storageadmin.middleware:32] Exception occurred while processing a request. Path: /api/commands/refresh-pool-state method: POST
[23/Aug/2019 14:17:18] ERROR [storageadmin.middleware:33] could not connect to server: No such file or directory
	Is the server running locally and accepting
	connections on Unix domain socket "/var/run/postgresql/.s.PGSQL.5432"?
Traceback (most recent call last):
  File "/opt/rockstor/eggs/Django-1.8.16-py2.7.egg/django/core/handlers/base.py", line 132, in get_response
    response = wrapped_callback(request, *callback_args, **callback_kwargs)
  File "/opt/rockstor/eggs/Django-1.8.16-py2.7.egg/django/views/decorators/csrf.py", line 58, in wrapped_view
    return view_func(*args, **kwargs)
  File "/opt/rockstor/eggs/Django-1.8.16-py2.7.egg/django/views/generic/base.py", line 71, in view
    return self.dispatch(request, *args, **kwargs)
  File "/opt/rockstor/eggs/djangorestframework-3.1.1-py2.7.egg/rest_framework/views.py", line 452, in dispatch
    response = self.handle_exception(exc)
  File "/opt/rockstor/eggs/djangorestframework-3.1.1-py2.7.egg/rest_framework/views.py", line 440, in dispatch
    self.initial(request, *args, **kwargs)
  File "/opt/rockstor/eggs/djangorestframework-3.1.1-py2.7.egg/rest_framework/views.py", line 354, in initial
    self.perform_authentication(request)
  File "/opt/rockstor/eggs/djangorestframework-3.1.1-py2.7.egg/rest_framework/views.py", line 292, in perform_authentication
    request.user
  File "/opt/rockstor/eggs/djangorestframework-3.1.1-py2.7.egg/rest_framework/request.py", line 491, in __getattribute__
    return super(Request, self).__getattribute__(attr)
  File "/opt/rockstor/eggs/djangorestframework-3.1.1-py2.7.egg/rest_framework/request.py", line 266, in user
    self._authenticate()
  File "/opt/rockstor/eggs/djangorestframework-3.1.1-py2.7.egg/rest_framework/request.py", line 454, in _authenticate
    user_auth_tuple = authenticator.authenticate(self)
  File "/opt/rockstor/src/rockstor/rest_framework_custom/oauth_wrapper.py", line 29, in authenticate
    creds = super(RockstorOAuth2Authentication, self).authenticate(request)
  File "/opt/rockstor/eggs/django_oauth_toolkit-0.9.0-py2.7.egg/oauth2_provider/ext/rest_framework/authentication.py", line 18, in authenticate
    valid, r = oauthlib_core.verify_request(request, scopes=[])
  File "/opt/rockstor/eggs/django_oauth_toolkit-0.9.0-py2.7.egg/oauth2_provider/oauth2_backends.py", line 155, in verify_request
    valid, r = self.server.verify_request(uri, http_method, body, headers, scopes=scopes)
  File "/opt/rockstor/eggs/oauthlib-1.0.1-py2.7.egg/oauthlib/oauth2/rfc6749/endpoints/base.py", line 64, in wrapper
    return f(endpoint, uri, *args, **kwargs)
  File "/opt/rockstor/eggs/oauthlib-1.0.1-py2.7.egg/oauthlib/oauth2/rfc6749/endpoints/resource.py", line 75, in verify_request
    return token_type_handler.validate_request(request), request
  File "/opt/rockstor/eggs/oauthlib-1.0.1-py2.7.egg/oauthlib/oauth2/rfc6749/tokens.py", line 286, in validate_request
    token, request.scopes, request)
  File "/opt/rockstor/eggs/django_oauth_toolkit-0.9.0-py2.7.egg/oauth2_provider/oauth2_validators.py", line 224, in validate_bearer_token
    token=token)
  File "/opt/rockstor/eggs/Django-1.8.16-py2.7.egg/django/db/models/query.py", line 328, in get
    num = len(clone)
  File "/opt/rockstor/eggs/Django-1.8.16-py2.7.egg/django/db/models/query.py", line 144, in __len__
    self._fetch_all()
  File "/opt/rockstor/eggs/Django-1.8.16-py2.7.egg/django/db/models/query.py", line 965, in _fetch_all
    self._result_cache = list(self.iterator())
  File "/opt/rockstor/eggs/Django-1.8.16-py2.7.egg/django/db/models/query.py", line 238, in iterator
    results = compiler.execute_sql()
  File "/opt/rockstor/eggs/Django-1.8.16-py2.7.egg/django/db/models/sql/compiler.py", line 838, in execute_sql
    cursor = self.connection.cursor()
  File "/opt/rockstor/eggs/Django-1.8.16-py2.7.egg/django/db/backends/base/base.py", line 162, in cursor
    cursor = self.make_debug_cursor(self._cursor())
  File "/opt/rockstor/eggs/Django-1.8.16-py2.7.egg/django/db/backends/base/base.py", line 135, in _cursor
    self.ensure_connection()
  File "/opt/rockstor/eggs/Django-1.8.16-py2.7.egg/django/db/backends/base/base.py", line 130, in ensure_connection
    self.connect()
  File "/opt/rockstor/eggs/Django-1.8.16-py2.7.egg/django/db/utils.py", line 98, in __exit__
    six.reraise(dj_exc_type, dj_exc_value, traceback)
  File "/opt/rockstor/eggs/Django-1.8.16-py2.7.egg/django/db/backends/base/base.py", line 130, in ensure_connection
    self.connect()
  File "/opt/rockstor/eggs/Django-1.8.16-py2.7.egg/django/db/backends/base/base.py", line 119, in connect
    self.connection = self.get_new_connection(conn_params)
  File "/opt/rockstor/eggs/Django-1.8.16-py2.7.egg/django/db/backends/postgresql_psycopg2/base.py", line 176, in get_new_connection
    connection = Database.connect(**conn_params)
  File "/usr/lib64/python2.7/site-packages/psycopg2/__init__.py", line 126, in connect
    conn = _connect(dsn, connection_factory=connection_factory, **kwasync)
OperationalError: could not connect to server: No such file or directory
	Is the server running locally and accepting
	connections on Unix domain socket "/var/run/postgresql/.s.PGSQL.5432"?

[23/Aug/2019 14:17:18] ERROR [storageadmin.middleware:32] Exception occurred while processing a request. Path: /api/commands/refresh-share-state method: POST
[23/Aug/2019 14:17:18] ERROR [storageadmin.middleware:33] could not connect to server: No such file or directory
	Is the server running locally and accepting
	connections on Unix domain socket "/var/run/postgresql/.s.PGSQL.5432"?
Traceback (most recent call last):
  File "/opt/rockstor/eggs/Django-1.8.16-py2.7.egg/django/core/handlers/base.py", line 132, in get_response
    response = wrapped_callback(request, *callback_args, **callback_kwargs)
  File "/opt/rockstor/eggs/Django-1.8.16-py2.7.egg/django/views/decorators/csrf.py", line 58, in wrapped_view
    return view_func(*args, **kwargs)
  File "/opt/rockstor/eggs/Django-1.8.16-py2.7.egg/django/views/generic/base.py", line 71, in view
    return self.dispatch(request, *args, **kwargs)
  File "/opt/rockstor/eggs/djangorestframework-3.1.1-py2.7.egg/rest_framework/views.py", line 452, in dispatch
    response = self.handle_exception(exc)
  File "/opt/rockstor/eggs/djangorestframework-3.1.1-py2.7.egg/rest_framework/views.py", line 440, in dispatch
    self.initial(request, *args, **kwargs)
  File "/opt/rockstor/eggs/djangorestframework-3.1.1-py2.7.egg/rest_framework/views.py", line 354, in initial
    self.perform_authentication(request)
  File "/opt/rockstor/eggs/djangorestframework-3.1.1-py2.7.egg/rest_framework/views.py", line 292, in perform_authentication
    request.user
  File "/opt/rockstor/eggs/djangorestframework-3.1.1-py2.7.egg/rest_framework/request.py", line 491, in __getattribute__
    return super(Request, self).__getattribute__(attr)
  File "/opt/rockstor/eggs/djangorestframework-3.1.1-py2.7.egg/rest_framework/request.py", line 266, in user
    self._authenticate()
  File "/opt/rockstor/eggs/djangorestframework-3.1.1-py2.7.egg/rest_framework/request.py", line 454, in _authenticate
    user_auth_tuple = authenticator.authenticate(self)
  File "/opt/rockstor/src/rockstor/rest_framework_custom/oauth_wrapper.py", line 29, in authenticate
    creds = super(RockstorOAuth2Authentication, self).authenticate(request)
  File "/opt/rockstor/eggs/django_oauth_toolkit-0.9.0-py2.7.egg/oauth2_provider/ext/rest_framework/authentication.py", line 18, in authenticate
    valid, r = oauthlib_core.verify_request(request, scopes=[])
  File "/opt/rockstor/eggs/django_oauth_toolkit-0.9.0-py2.7.egg/oauth2_provider/oauth2_backends.py", line 155, in verify_request
    valid, r = self.server.verify_request(uri, http_method, body, headers, scopes=scopes)
  File "/opt/rockstor/eggs/oauthlib-1.0.1-py2.7.egg/oauthlib/oauth2/rfc6749/endpoints/base.py", line 64, in wrapper
    return f(endpoint, uri, *args, **kwargs)
  File "/opt/rockstor/eggs/oauthlib-1.0.1-py2.7.egg/oauthlib/oauth2/rfc6749/endpoints/resource.py", line 75, in verify_request
    return token_type_handler.validate_request(request), request
  File "/opt/rockstor/eggs/oauthlib-1.0.1-py2.7.egg/oauthlib/oauth2/rfc6749/tokens.py", line 286, in validate_request
    token, request.scopes, request)
  File "/opt/rockstor/eggs/django_oauth_toolkit-0.9.0-py2.7.egg/oauth2_provider/oauth2_validators.py", line 224, in validate_bearer_token
    token=token)
  File "/opt/rockstor/eggs/Django-1.8.16-py2.7.egg/django/db/models/query.py", line 328, in get
    num = len(clone)
  File "/opt/rockstor/eggs/Django-1.8.16-py2.7.egg/django/db/models/query.py", line 144, in __len__
    self._fetch_all()
  File "/opt/rockstor/eggs/Django-1.8.16-py2.7.egg/django/db/models/query.py", line 965, in _fetch_all
    self._result_cache = list(self.iterator())
  File "/opt/rockstor/eggs/Django-1.8.16-py2.7.egg/django/db/models/query.py", line 238, in iterator
    results = compiler.execute_sql()
  File "/opt/rockstor/eggs/Django-1.8.16-py2.7.egg/django/db/models/sql/compiler.py", line 838, in execute_sql
    cursor = self.connection.cursor()
  File "/opt/rockstor/eggs/Django-1.8.16-py2.7.egg/django/db/backends/base/base.py", line 162, in cursor
    cursor = self.make_debug_cursor(self._cursor())
  File "/opt/rockstor/eggs/Django-1.8.16-py2.7.egg/django/db/backends/base/base.py", line 135, in _cursor
    self.ensure_connection()
  File "/opt/rockstor/eggs/Django-1.8.16-py2.7.egg/django/db/backends/base/base.py", line 130, in ensure_connection
    self.connect()
  File "/opt/rockstor/eggs/Django-1.8.16-py2.7.egg/django/db/utils.py", line 98, in __exit__
    six.reraise(dj_exc_type, dj_exc_value, traceback)
  File "/opt/rockstor/eggs/Django-1.8.16-py2.7.egg/django/db/backends/base/base.py", line 130, in ensure_connection
    self.connect()
  File "/opt/rockstor/eggs/Django-1.8.16-py2.7.egg/django/db/backends/base/base.py", line 119, in connect
    self.connection = self.get_new_connection(conn_params)
  File "/opt/rockstor/eggs/Django-1.8.16-py2.7.egg/django/db/backends/postgresql_psycopg2/base.py", line 176, in get_new_connection
    connection = Database.connect(**conn_params)
  File "/usr/lib64/python2.7/site-packages/psycopg2/__init__.py", line 126, in connect
    conn = _connect(dsn, connection_factory=connection_factory, **kwasync)
OperationalError: could not connect to server: No such file or directory
	Is the server running locally and accepting
	connections on Unix domain socket "/var/run/postgresql/.s.PGSQL.5432"?

[23/Aug/2019 14:17:18] ERROR [storageadmin.middleware:32] Exception occurred while processing a request. Path: /api/commands/refresh-snapshot-state method: POST
[23/Aug/2019 14:17:18] ERROR [storageadmin.middleware:33] could not connect to server: No such file or directory
	Is the server running locally and accepting
	connections on Unix domain socket "/var/run/postgresql/.s.PGSQL.5432"?
Traceback (most recent call last):
  File "/opt/rockstor/eggs/Django-1.8.16-py2.7.egg/django/core/handlers/base.py", line 132, in get_response
    response = wrapped_callback(request, *callback_args, **callback_kwargs)
  File "/opt/rockstor/eggs/Django-1.8.16-py2.7.egg/django/views/decorators/csrf.py", line 58, in wrapped_view
    return view_func(*args, **kwargs)
  File "/opt/rockstor/eggs/Django-1.8.16-py2.7.egg/django/views/generic/base.py", line 71, in view
    return self.dispatch(request, *args, **kwargs)
  File "/opt/rockstor/eggs/djangorestframework-3.1.1-py2.7.egg/rest_framework/views.py", line 452, in dispatch
    response = self.handle_exception(exc)
  File "/opt/rockstor/eggs/djangorestframework-3.1.1-py2.7.egg/rest_framework/views.py", line 440, in dispatch
    self.initial(request, *args, **kwargs)
  File "/opt/rockstor/eggs/djangorestframework-3.1.1-py2.7.egg/rest_framework/views.py", line 354, in initial
    self.perform_authentication(request)
  File "/opt/rockstor/eggs/djangorestframework-3.1.1-py2.7.egg/rest_framework/views.py", line 292, in perform_authentication
    request.user
  File "/opt/rockstor/eggs/djangorestframework-3.1.1-py2.7.egg/rest_framework/request.py", line 491, in __getattribute__
    return super(Request, self).__getattribute__(attr)
  File "/opt/rockstor/eggs/djangorestframework-3.1.1-py2.7.egg/rest_framework/request.py", line 266, in user
    self._authenticate()
  File "/opt/rockstor/eggs/djangorestframework-3.1.1-py2.7.egg/rest_framework/request.py", line 454, in _authenticate
    user_auth_tuple = authenticator.authenticate(self)
  File "/opt/rockstor/src/rockstor/rest_framework_custom/oauth_wrapper.py", line 29, in authenticate
    creds = super(RockstorOAuth2Authentication, self).authenticate(request)
  File "/opt/rockstor/eggs/django_oauth_toolkit-0.9.0-py2.7.egg/oauth2_provider/ext/rest_framework/authentication.py", line 18, in authenticate
    valid, r = oauthlib_core.verify_request(request, scopes=[])
  File "/opt/rockstor/eggs/django_oauth_toolkit-0.9.0-py2.7.egg/oauth2_provider/oauth2_backends.py", line 155, in verify_request
    valid, r = self.server.verify_request(uri, http_method, body, headers, scopes=scopes)
  File "/opt/rockstor/eggs/oauthlib-1.0.1-py2.7.egg/oauthlib/oauth2/rfc6749/endpoints/base.py", line 64, in wrapper
    return f(endpoint, uri, *args, **kwargs)
  File "/opt/rockstor/eggs/oauthlib-1.0.1-py2.7.egg/oauthlib/oauth2/rfc6749/endpoints/resource.py", line 75, in verify_request
    return token_type_handler.validate_request(request), request
  File "/opt/rockstor/eggs/oauthlib-1.0.1-py2.7.egg/oauthlib/oauth2/rfc6749/tokens.py", line 286, in validate_request
    token, request.scopes, request)
  File "/opt/rockstor/eggs/django_oauth_toolkit-0.9.0-py2.7.egg/oauth2_provider/oauth2_validators.py", line 224, in validate_bearer_token
    token=token)
  File "/opt/rockstor/eggs/Django-1.8.16-py2.7.egg/django/db/models/query.py", line 328, in get
    num = len(clone)
  File "/opt/rockstor/eggs/Django-1.8.16-py2.7.egg/django/db/models/query.py", line 144, in __len__
    self._fetch_all()
  File "/opt/rockstor/eggs/Django-1.8.16-py2.7.egg/django/db/models/query.py", line 965, in _fetch_all
    self._result_cache = list(self.iterator())
  File "/opt/rockstor/eggs/Django-1.8.16-py2.7.egg/django/db/models/query.py", line 238, in iterator
    results = compiler.execute_sql()
  File "/opt/rockstor/eggs/Django-1.8.16-py2.7.egg/django/db/models/sql/compiler.py", line 838, in execute_sql
    cursor = self.connection.cursor()
  File "/opt/rockstor/eggs/Django-1.8.16-py2.7.egg/django/db/backends/base/base.py", line 162, in cursor
    cursor = self.make_debug_cursor(self._cursor())
  File "/opt/rockstor/eggs/Django-1.8.16-py2.7.egg/django/db/backends/base/base.py", line 135, in _cursor
    self.ensure_connection()
  File "/opt/rockstor/eggs/Django-1.8.16-py2.7.egg/django/db/backends/base/base.py", line 130, in ensure_connection
    self.connect()
  File "/opt/rockstor/eggs/Django-1.8.16-py2.7.egg/django/db/utils.py", line 98, in __exit__
    six.reraise(dj_exc_type, dj_exc_value, traceback)
  File "/opt/rockstor/eggs/Django-1.8.16-py2.7.egg/django/db/backends/base/base.py", line 130, in ensure_connection
    self.connect()
  File "/opt/rockstor/eggs/Django-1.8.16-py2.7.egg/django/db/backends/base/base.py", line 119, in connect
    self.connection = self.get_new_connection(conn_params)
  File "/opt/rockstor/eggs/Django-1.8.16-py2.7.egg/django/db/backends/postgresql_psycopg2/base.py", line 176, in get_new_connection
    connection = Database.connect(**conn_params)
  File "/usr/lib64/python2.7/site-packages/psycopg2/__init__.py", line 126, in connect
    conn = _connect(dsn, connection_factory=connection_factory, **kwasync)
OperationalError: could not connect to server: No such file or directory
	Is the server running locally and accepting
	connections on Unix domain socket "/var/run/postgresql/.s.PGSQL.5432"?

[23/Aug/2019 14:17:34] ERROR [storageadmin.middleware:32] Exception occurred while processing a request. Path: / method: GET
[23/Aug/2019 14:17:34] ERROR [storageadmin.middleware:33] could not connect to server: No such file or directory
	Is the server running locally and accepting
	connections on Unix domain socket "/var/run/postgresql/.s.PGSQL.5432"?
Traceback (most recent call last):
  File "/opt/rockstor/eggs/Django-1.8.16-py2.7.egg/django/core/handlers/base.py", line 132, in get_response
    response = wrapped_callback(request, *callback_args, **callback_kwargs)
  File "/opt/rockstor/src/rockstor/storageadmin/views/home.py", line 54, in home
    setup = Setup.objects.all()[0]
  File "/opt/rockstor/eggs/Django-1.8.16-py2.7.egg/django/db/models/query.py", line 201, in __getitem__
    return list(qs)[0]
  File "/opt/rockstor/eggs/Django-1.8.16-py2.7.egg/django/db/models/query.py", line 162, in __iter__
    self._fetch_all()
  File "/opt/rockstor/eggs/Django-1.8.16-py2.7.egg/django/db/models/query.py", line 965, in _fetch_all
    self._result_cache = list(self.iterator())
  File "/opt/rockstor/eggs/Django-1.8.16-py2.7.egg/django/db/models/query.py", line 238, in iterator
    results = compiler.execute_sql()
  File "/opt/rockstor/eggs/Django-1.8.16-py2.7.egg/django/db/models/sql/compiler.py", line 838, in execute_sql
    cursor = self.connection.cursor()
  File "/opt/rockstor/eggs/Django-1.8.16-py2.7.egg/django/db/backends/base/base.py", line 162, in cursor
    cursor = self.make_debug_cursor(self._cursor())
  File "/opt/rockstor/eggs/Django-1.8.16-py2.7.egg/django/db/backends/base/base.py", line 135, in _cursor
    self.ensure_connection()
  File "/opt/rockstor/eggs/Django-1.8.16-py2.7.egg/django/db/backends/base/base.py", line 130, in ensure_connection
    self.connect()
  File "/opt/rockstor/eggs/Django-1.8.16-py2.7.egg/django/db/utils.py", line 98, in __exit__
    six.reraise(dj_exc_type, dj_exc_value, traceback)
  File "/opt/rockstor/eggs/Django-1.8.16-py2.7.egg/django/db/backends/base/base.py", line 130, in ensure_connection
    self.connect()
  File "/opt/rockstor/eggs/Django-1.8.16-py2.7.egg/django/db/backends/base/base.py", line 119, in connect
    self.connection = self.get_new_connection(conn_params)
  File "/opt/rockstor/eggs/Django-1.8.16-py2.7.egg/django/db/backends/postgresql_psycopg2/base.py", line 176, in get_new_connection
    connection = Database.connect(**conn_params)
  File "/usr/lib64/python2.7/site-packages/psycopg2/__init__.py", line 126, in connect
    conn = _connect(dsn, connection_factory=connection_factory, **kwasync)
OperationalError: could not connect to server: No such file or directory
	Is the server running locally and accepting
	connections on Unix domain socket "/var/run/postgresql/.s.PGSQL.5432"?

[23/Aug/2019 14:17:36] ERROR [storageadmin.middleware:32] Exception occurred while processing a request. Path: / method: GET
[23/Aug/2019 14:17:36] ERROR [storageadmin.middleware:33] could not connect to server: No such file or directory
	Is the server running locally and accepting
	connections on Unix domain socket "/var/run/postgresql/.s.PGSQL.5432"?
Traceback (most recent call last):
  File "/opt/rockstor/eggs/Django-1.8.16-py2.7.egg/django/core/handlers/base.py", line 132, in get_response
    response = wrapped_callback(request, *callback_args, **callback_kwargs)
  File "/opt/rockstor/src/rockstor/storageadmin/views/home.py", line 54, in home
    setup = Setup.objects.all()[0]
  File "/opt/rockstor/eggs/Django-1.8.16-py2.7.egg/django/db/models/query.py", line 201, in __getitem__
    return list(qs)[0]
  File "/opt/rockstor/eggs/Django-1.8.16-py2.7.egg/django/db/models/query.py", line 162, in __iter__
    self._fetch_all()
  File "/opt/rockstor/eggs/Django-1.8.16-py2.7.egg/django/db/models/query.py", line 965, in _fetch_all
    self._result_cache = list(self.iterator())
  File "/opt/rockstor/eggs/Django-1.8.16-py2.7.egg/django/db/models/query.py", line 238, in iterator
    results = compiler.execute_sql()
  File "/opt/rockstor/eggs/Django-1.8.16-py2.7.egg/django/db/models/sql/compiler.py", line 838, in execute_sql
    cursor = self.connection.cursor()
  File "/opt/rockstor/eggs/Django-1.8.16-py2.7.egg/django/db/backends/base/base.py", line 162, in cursor
    cursor = self.make_debug_cursor(self._cursor())
  File "/opt/rockstor/eggs/Django-1.8.16-py2.7.egg/django/db/backends/base/base.py", line 135, in _cursor
    self.ensure_connection()
  File "/opt/rockstor/eggs/Django-1.8.16-py2.7.egg/django/db/backends/base/base.py", line 130, in ensure_connection
    self.connect()
  File "/opt/rockstor/eggs/Django-1.8.16-py2.7.egg/django/db/utils.py", line 98, in __exit__
    six.reraise(dj_exc_type, dj_exc_value, traceback)
  File "/opt/rockstor/eggs/Django-1.8.16-py2.7.egg/django/db/backends/base/base.py", line 130, in ensure_connection
    self.connect()
  File "/opt/rockstor/eggs/Django-1.8.16-py2.7.egg/django/db/backends/base/base.py", line 119, in connect
    self.connection = self.get_new_connection(conn_params)
  File "/opt/rockstor/eggs/Django-1.8.16-py2.7.egg/django/db/backends/postgresql_psycopg2/base.py", line 176, in get_new_connection
    connection = Database.connect(**conn_params)
  File "/usr/lib64/python2.7/site-packages/psycopg2/__init__.py", line 126, in connect
    conn = _connect(dsn, connection_factory=connection_factory, **kwasync)
OperationalError: could not connect to server: No such file or directory
	Is the server running locally and accepting
	connections on Unix domain socket "/var/run/postgresql/.s.PGSQL.5432"?

[23/Aug/2019 14:17:48] ERROR [storageadmin.middleware:32] Exception occurred while processing a request. Path: /api/commands/refresh-share-state method: POST
[23/Aug/2019 14:17:48] ERROR [storageadmin.middleware:33] Exception while running command(['sss', 'subvolume', 'list', '-s', '0']): [Errno 2] No such file or directory
Traceback (most recent call last):
  File "/opt/rockstor/eggs/Django-1.8.16-py2.7.egg/django/core/handlers/base.py", line 132, in get_response
    response = wrapped_callback(request, *callback_args, **callback_kwargs)
  File "/opt/rockstor/eggs/Django-1.8.16-py2.7.egg/django/views/decorators/csrf.py", line 58, in wrapped_view
    return view_func(*args, **kwargs)
  File "/opt/rockstor/eggs/Django-1.8.16-py2.7.egg/django/views/generic/base.py", line 71, in view
    return self.dispatch(request, *args, **kwargs)
  File "/opt/rockstor/eggs/djangorestframework-3.1.1-py2.7.egg/rest_framework/views.py", line 452, in dispatch
    response = self.handle_exception(exc)
  File "/opt/rockstor/eggs/djangorestframework-3.1.1-py2.7.egg/rest_framework/views.py", line 449, in dispatch
    response = handler(request, *args, **kwargs)
  File "/opt/rockstor/eggs/Django-1.8.16-py2.7.egg/django/utils/decorators.py", line 145, in inner
    return func(*args, **kwargs)
  File "/opt/rockstor/src/rockstor/storageadmin/views/command.py", line 345, in post
    import_shares(p, request)
  File "/opt/rockstor/src/rockstor/storageadmin/views/share_helpers.py", line 86, in import_shares
    shares_in_pool = shares_info(pool)
  File "/opt/rockstor/src/rockstor/fs/btrfs.py", line 650, in shares_info
    snap_idmap = snapshot_idmap(pool_mnt_pt)
  File "/opt/rockstor/src/rockstor/fs/btrfs.py", line 618, in snapshot_idmap
    out, e, rc = run_command([BTRFS, 'subvolume', 'list', '-s', pool_mnt_pt])
  File "/opt/rockstor/src/rockstor/system/osi.py", line 113, in run_command
    'Exception while running command({}): {}'.format(cmd, e))
Exception: Exception while running command(['sss', 'subvolume', 'list', '-s', '0']): [Errno 2] No such file or directory
[23/Aug/2019 14:17:49] ERROR [storageadmin.middleware:32] Exception occurred while processing a request. Path: /api/commands/refresh-snapshot-state method: POST
[23/Aug/2019 14:17:49] ERROR [storageadmin.middleware:33] Exception while running command(['sss', 'subvolume', 'list', '-u', '-p', '-q', '/po']): [Errno 2] No such file or directory
Traceback (most recent call last):
  File "/opt/rockstor/eggs/Django-1.8.16-py2.7.egg/django/core/handlers/base.py", line 132, in get_response
    response = wrapped_callback(request, *callback_args, **callback_kwargs)
  File "/opt/rockstor/eggs/Django-1.8.16-py2.7.egg/django/views/decorators/csrf.py", line 58, in wrapped_view
    return view_func(*args, **kwargs)
  File "/opt/rockstor/eggs/Django-1.8.16-py2.7.egg/django/views/generic/base.py", line 71, in view
    return self.dispatch(request, *args, **kwargs)
  File "/opt/rockstor/eggs/djangorestframework-3.1.1-py2.7.egg/rest_framework/views.py", line 452, in dispatch
    response = self.handle_exception(exc)
  File "/opt/rockstor/eggs/djangorestframework-3.1.1-py2.7.egg/rest_framework/views.py", line 449, in dispatch
    response = handler(request, *args, **kwargs)
  File "/opt/rockstor/eggs/Django-1.8.16-py2.7.egg/django/utils/decorators.py", line 145, in inner
    return func(*args, **kwargs)
  File "/opt/rockstor/src/rockstor/storageadmin/views/command.py", line 350, in post
    import_snapshots(share)
  File "/opt/rockstor/src/rockstor/storageadmin/views/share_helpers.py", line 209, in import_snapshots
    share.name)
  File "/opt/rockstor/src/rockstor/fs/btrfs.py", line 749, in snaps_info
    pool_mnt_pt])
  File "/opt/rockstor/src/rockstor/system/osi.py", line 113, in run_command
    'Exception while running command({}): {}'.format(cmd, e))
Exception: Exception while running command(['sss', 'subvolume', 'list', '-u', '-p', '-q', '/po']): [Errno 2] No such file or directory
[23/Aug/2019 14:17:53] ERROR [storageadmin.util:44] Exception: unsupported operand type(s) for +: 'NoneType' and 'str'
Traceback (most recent call last):
  File "/opt/rockstor/src/rockstor/rest_framework_custom/generic_view.py", line 41, in _handle_exception
    yield
  File "/opt/rockstor/src/rockstor/storageadmin/views/disk.py", line 416, in post
    return self._update_disk_state()
  File "/opt/rockstor/eggs/Django-1.8.16-py2.7.egg/django/utils/decorators.py", line 145, in inner
    return func(*args, **kwargs)
  File "/opt/rockstor/src/rockstor/storageadmin/views/disk.py", line 75, in _update_disk_state
    disks = scan_disks(settings.MIN_DISK_SIZE)
  File "/opt/rockstor/src/rockstor/system/osi.py", line 380, in scan_disks
    part_regex = base_root_disk + '\d+'
TypeError: unsupported operand type(s) for +: 'NoneType' and 'str'
[23/Aug/2019 14:17:53] DEBUG [storageadmin.util:45] Current Rockstor version: Unknown Version
[23/Aug/2019 14:19:49] ERROR [storageadmin.util:44] Exception: unsupported operand type(s) for +: 'NoneType' and 'str'
Traceback (most recent call last):
  File "/opt/rockstor/src/rockstor/rest_framework_custom/generic_view.py", line 41, in _handle_exception
    yield
  File "/opt/rockstor/src/rockstor/storageadmin/views/disk.py", line 416, in post
    return self._update_disk_state()
  File "/opt/rockstor/eggs/Django-1.8.16-py2.7.egg/django/utils/decorators.py", line 145, in inner
    return func(*args, **kwargs)
  File "/opt/rockstor/src/rockstor/storageadmin/views/disk.py", line 75, in _update_disk_state
    disks = scan_disks(settings.MIN_DISK_SIZE)
  File "/opt/rockstor/src/rockstor/system/osi.py", line 380, in scan_disks
    part_regex = base_root_disk + '\d+'
TypeError: unsupported operand type(s) for +: 'NoneType' and 'str'
[23/Aug/2019 14:19:49] DEBUG [storageadmin.util:45] Current Rockstor version: Unknown Version
[23/Aug/2019 14:19:49] ERROR [storageadmin.views.command:99] Exception while refreshing state for Pool(po). Moving on: Exception while running command(['sss', 'fi', 'show', '/dev/disk/by-id/wwn-0x6000c291b069fa5b74bc17fa8ebcf907']): [Errno 2] No such file or directory
[23/Aug/2019 14:19:49] ERROR [storageadmin.views.command:100] Exception while running command(['sss', 'fi', 'show', '/dev/disk/by-id/wwn-0x6000c291b069fa5b74bc17fa8ebcf907']): [Errno 2] No such file or directory
Traceback (most recent call last):
  File "/opt/rockstor/src/rockstor/storageadmin/views/command.py", line 80, in _refresh_pool_state
    is_root_pool)
  File "/opt/rockstor/src/rockstor/fs/btrfs.py", line 260, in get_pool_info
    o, e, rc = run_command(cmd)
  File "/opt/rockstor/src/rockstor/system/osi.py", line 113, in run_command
    'Exception while running command({}): {}'.format(cmd, e))
Exception: Exception while running command(['sss', 'fi', 'show', '/dev/disk/by-id/wwn-0x6000c291b069fa5b74bc17fa8ebcf907']): [Errno 2] No such file or directory
[23/Aug/2019 14:19:49] ERROR [storageadmin.middleware:32] Exception occurred while processing a request. Path: /api/commands/refresh-share-state method: POST
[23/Aug/2019 14:19:49] ERROR [storageadmin.middleware:33] Exception while running command(['sss', 'subvolume', 'list', '-s', '0']): [Errno 2] No such file or directory
Traceback (most recent call last):
  File "/opt/rockstor/eggs/Django-1.8.16-py2.7.egg/django/core/handlers/base.py", line 132, in get_response
    response = wrapped_callback(request, *callback_args, **callback_kwargs)
  File "/opt/rockstor/eggs/Django-1.8.16-py2.7.egg/django/views/decorators/csrf.py", line 58, in wrapped_view
    return view_func(*args, **kwargs)
  File "/opt/rockstor/eggs/Django-1.8.16-py2.7.egg/django/views/generic/base.py", line 71, in view
    return self.dispatch(request, *args, **kwargs)
  File "/opt/rockstor/eggs/djangorestframework-3.1.1-py2.7.egg/rest_framework/views.py", line 452, in dispatch
    response = self.handle_exception(exc)
  File "/opt/rockstor/eggs/djangorestframework-3.1.1-py2.7.egg/rest_framework/views.py", line 449, in dispatch
    response = handler(request, *args, **kwargs)
  File "/opt/rockstor/eggs/Django-1.8.16-py2.7.egg/django/utils/decorators.py", line 145, in inner
    return func(*args, **kwargs)
  File "/opt/rockstor/src/rockstor/storageadmin/views/command.py", line 345, in post
    import_shares(p, request)
  File "/opt/rockstor/src/rockstor/storageadmin/views/share_helpers.py", line 86, in import_shares
    shares_in_pool = shares_info(pool)
  File "/opt/rockstor/src/rockstor/fs/btrfs.py", line 650, in shares_info
    snap_idmap = snapshot_idmap(pool_mnt_pt)
  File "/opt/rockstor/src/rockstor/fs/btrfs.py", line 618, in snapshot_idmap
    out, e, rc = run_command([BTRFS, 'subvolume', 'list', '-s', pool_mnt_pt])
  File "/opt/rockstor/src/rockstor/system/osi.py", line 113, in run_command
    'Exception while running command({}): {}'.format(cmd, e))
Exception: Exception while running command(['sss', 'subvolume', 'list', '-s', '0']): [Errno 2] No such file or directory
[23/Aug/2019 14:20:50] ERROR [storageadmin.util:44] Exception: unsupported operand type(s) for +: 'NoneType' and 'str'
Traceback (most recent call last):
  File "/opt/rockstor/src/rockstor/rest_framework_custom/generic_view.py", line 41, in _handle_exception
    yield
  File "/opt/rockstor/src/rockstor/storageadmin/views/disk.py", line 416, in post
    return self._update_disk_state()
  File "/opt/rockstor/eggs/Django-1.8.16-py2.7.egg/django/utils/decorators.py", line 145, in inner
    return func(*args, **kwargs)
  File "/opt/rockstor/src/rockstor/storageadmin/views/disk.py", line 75, in _update_disk_state
    disks = scan_disks(settings.MIN_DISK_SIZE)
  File "/opt/rockstor/src/rockstor/system/osi.py", line 380, in scan_disks
    part_regex = base_root_disk + '\d+'
TypeError: unsupported operand type(s) for +: 'NoneType' and 'str'
[23/Aug/2019 14:20:50] DEBUG [storageadmin.util:45] Current Rockstor version: Unknown Version
[23/Aug/2019 14:20:50] ERROR [storageadmin.views.command:99] Exception while refreshing state for Pool(po). Moving on: Exception while running command(['sss', 'fi', 'show', '/dev/disk/by-id/wwn-0x6000c291b069fa5b74bc17fa8ebcf907']): [Errno 2] No such file or directory
[23/Aug/2019 14:20:50] ERROR [storageadmin.views.command:100] Exception while running command(['sss', 'fi', 'show', '/dev/disk/by-id/wwn-0x6000c291b069fa5b74bc17fa8ebcf907']): [Errno 2] No such file or directory
Traceback (most recent call last):
  File "/opt/rockstor/src/rockstor/storageadmin/views/command.py", line 80, in _refresh_pool_state
    is_root_pool)
  File "/opt/rockstor/src/rockstor/fs/btrfs.py", line 260, in get_pool_info
    o, e, rc = run_command(cmd)
  File "/opt/rockstor/src/rockstor/system/osi.py", line 113, in run_command
    'Exception while running command({}): {}'.format(cmd, e))
Exception: Exception while running command(['sss', 'fi', 'show', '/dev/disk/by-id/wwn-0x6000c291b069fa5b74bc17fa8ebcf907']): [Errno 2] No such file or directory
[23/Aug/2019 14:20:50] ERROR [storageadmin.middleware:32] Exception occurred while processing a request. Path: /api/commands/refresh-share-state method: POST
[23/Aug/2019 14:20:50] ERROR [storageadmin.middleware:33] Exception while running command(['sss', 'subvolume', 'list', '-s', '0']): [Errno 2] No such file or directory
Traceback (most recent call last):
  File "/opt/rockstor/eggs/Django-1.8.16-py2.7.egg/django/core/handlers/base.py", line 132, in get_response
    response = wrapped_callback(request, *callback_args, **callback_kwargs)
  File "/opt/rockstor/eggs/Django-1.8.16-py2.7.egg/django/views/decorators/csrf.py", line 58, in wrapped_view
    return view_func(*args, **kwargs)
  File "/opt/rockstor/eggs/Django-1.8.16-py2.7.egg/django/views/generic/base.py", line 71, in view
    return self.dispatch(request, *args, **kwargs)
  File "/opt/rockstor/eggs/djangorestframework-3.1.1-py2.7.egg/rest_framework/views.py", line 452, in dispatch
    response = self.handle_exception(exc)
  File "/opt/rockstor/eggs/djangorestframework-3.1.1-py2.7.egg/rest_framework/views.py", line 449, in dispatch
    response = handler(request, *args, **kwargs)
  File "/opt/rockstor/eggs/Django-1.8.16-py2.7.egg/django/utils/decorators.py", line 145, in inner
    return func(*args, **kwargs)
  File "/opt/rockstor/src/rockstor/storageadmin/views/command.py", line 345, in post
    import_shares(p, request)
  File "/opt/rockstor/src/rockstor/storageadmin/views/share_helpers.py", line 86, in import_shares
    shares_in_pool = shares_info(pool)
  File "/opt/rockstor/src/rockstor/fs/btrfs.py", line 650, in shares_info
    snap_idmap = snapshot_idmap(pool_mnt_pt)
  File "/opt/rockstor/src/rockstor/fs/btrfs.py", line 618, in snapshot_idmap
    out, e, rc = run_command([BTRFS, 'subvolume', 'list', '-s', pool_mnt_pt])
  File "/opt/rockstor/src/rockstor/system/osi.py", line 113, in run_command
    'Exception while running command({}): {}'.format(cmd, e))
Exception: Exception while running command(['sss', 'subvolume', 'list', '-s', '0']): [Errno 2] No such file or directory
[23/Aug/2019 14:20:50] ERROR [storageadmin.middleware:32] Exception occurred while processing a request. Path: /api/commands/refresh-snapshot-state method: POST
[23/Aug/2019 14:20:50] ERROR [storageadmin.middleware:33] Exception while running command(['sss', 'subvolume', 'list', '-u', '-p', '-q', '/po']): [Errno 2] No such file or directory
Traceback (most recent call last):
  File "/opt/rockstor/eggs/Django-1.8.16-py2.7.egg/django/core/handlers/base.py", line 132, in get_response
    response = wrapped_callback(request, *callback_args, **callback_kwargs)
  File "/opt/rockstor/eggs/Django-1.8.16-py2.7.egg/django/views/decorators/csrf.py", line 58, in wrapped_view
    return view_func(*args, **kwargs)
  File "/opt/rockstor/eggs/Django-1.8.16-py2.7.egg/django/views/generic/base.py", line 71, in view
    return self.dispatch(request, *args, **kwargs)
  File "/opt/rockstor/eggs/djangorestframework-3.1.1-py2.7.egg/rest_framework/views.py", line 452, in dispatch
    response = self.handle_exception(exc)
  File "/opt/rockstor/eggs/djangorestframework-3.1.1-py2.7.egg/rest_framework/views.py", line 449, in dispatch
    response = handler(request, *args, **kwargs)
  File "/opt/rockstor/eggs/Django-1.8.16-py2.7.egg/django/utils/decorators.py", line 145, in inner
    return func(*args, **kwargs)
  File "/opt/rockstor/src/rockstor/storageadmin/views/command.py", line 350, in post
    import_snapshots(share)
  File "/opt/rockstor/src/rockstor/storageadmin/views/share_helpers.py", line 209, in import_snapshots
    share.name)
  File "/opt/rockstor/src/rockstor/fs/btrfs.py", line 749, in snaps_info
    pool_mnt_pt])
  File "/opt/rockstor/src/rockstor/system/osi.py", line 113, in run_command
    'Exception while running command({}): {}'.format(cmd, e))
Exception: Exception while running command(['sss', 'subvolume', 'list', '-u', '-p', '-q', '/po']): [Errno 2] No such file or directory
[23/Aug/2019 14:21:50] ERROR [storageadmin.middleware:32] Exception occurred while processing a request. Path: /api/commands/refresh-share-state method: POST
[23/Aug/2019 14:21:50] ERROR [storageadmin.middleware:33] Exception while running command(['sss', 'subvolume', 'list', '-s', '0']): [Errno 2] No such file or directory
Traceback (most recent call last):
  File "/opt/rockstor/eggs/Django-1.8.16-py2.7.egg/django/core/handlers/base.py", line 132, in get_response
    response = wrapped_callback(request, *callback_args, **callback_kwargs)
  File "/opt/rockstor/eggs/Django-1.8.16-py2.7.egg/django/views/decorators/csrf.py", line 58, in wrapped_view
    return view_func(*args, **kwargs)
  File "/opt/rockstor/eggs/Django-1.8.16-py2.7.egg/django/views/generic/base.py", line 71, in view
    return self.dispatch(request, *args, **kwargs)
  File "/opt/rockstor/eggs/djangorestframework-3.1.1-py2.7.egg/rest_framework/views.py", line 452, in dispatch
    response = self.handle_exception(exc)
  File "/opt/rockstor/eggs/djangorestframework-3.1.1-py2.7.egg/rest_framework/views.py", line 449, in dispatch
    response = handler(request, *args, **kwargs)
  File "/opt/rockstor/eggs/Django-1.8.16-py2.7.egg/django/utils/decorators.py", line 145, in inner
    return func(*args, **kwargs)
  File "/opt/rockstor/src/rockstor/storageadmin/views/command.py", line 345, in post
    import_shares(p, request)
  File "/opt/rockstor/src/rockstor/storageadmin/views/share_helpers.py", line 86, in import_shares
    shares_in_pool = shares_info(pool)
  File "/opt/rockstor/src/rockstor/fs/btrfs.py", line 650, in shares_info
    snap_idmap = snapshot_idmap(pool_mnt_pt)
  File "/opt/rockstor/src/rockstor/fs/btrfs.py", line 618, in snapshot_idmap
    out, e, rc = run_command([BTRFS, 'subvolume', 'list', '-s', pool_mnt_pt])
  File "/opt/rockstor/src/rockstor/system/osi.py", line 113, in run_command
    'Exception while running command({}): {}'.format(cmd, e))
Exception: Exception while running command(['sss', 'subvolume', 'list', '-s', '0']): [Errno 2] No such file or directory
[23/Aug/2019 14:21:50] ERROR [storageadmin.middleware:32] Exception occurred while processing a request. Path: /api/commands/refresh-snapshot-state method: POST
[23/Aug/2019 14:21:50] ERROR [storageadmin.middleware:33] Exception while running command(['sss', 'subvolume', 'list', '-u', '-p', '-q', '/po']): [Errno 2] No such file or directory
Traceback (most recent call last):
  File "/opt/rockstor/eggs/Django-1.8.16-py2.7.egg/django/core/handlers/base.py", line 132, in get_response
    response = wrapped_callback(request, *callback_args, **callback_kwargs)
  File "/opt/rockstor/eggs/Django-1.8.16-py2.7.egg/django/views/decorators/csrf.py", line 58, in wrapped_view
    return view_func(*args, **kwargs)
  File "/opt/rockstor/eggs/Django-1.8.16-py2.7.egg/django/views/generic/base.py", line 71, in view
    return self.dispatch(request, *args, **kwargs)
  File "/opt/rockstor/eggs/djangorestframework-3.1.1-py2.7.egg/rest_framework/views.py", line 452, in dispatch
    response = self.handle_exception(exc)
  File "/opt/rockstor/eggs/djangorestframework-3.1.1-py2.7.egg/rest_framework/views.py", line 449, in dispatch
    response = handler(request, *args, **kwargs)
  File "/opt/rockstor/eggs/Django-1.8.16-py2.7.egg/django/utils/decorators.py", line 145, in inner
    return func(*args, **kwargs)
  File "/opt/rockstor/src/rockstor/storageadmin/views/command.py", line 350, in post
    import_snapshots(share)
  File "/opt/rockstor/src/rockstor/storageadmin/views/share_helpers.py", line 209, in import_snapshots
    share.name)
  File "/opt/rockstor/src/rockstor/fs/btrfs.py", line 749, in snaps_info
    pool_mnt_pt])
  File "/opt/rockstor/src/rockstor/system/osi.py", line 113, in run_command
    'Exception while running command({}): {}'.format(cmd, e))
Exception: Exception while running command(['sss', 'subvolume', 'list', '-u', '-p', '-q', '/po']): [Errno 2] No such file or directory
[23/Aug/2019 14:22:50] ERROR [storageadmin.middleware:32] Exception occurred while processing a request. Path: /api/commands/refresh-share-state method: POST
[23/Aug/2019 14:22:50] ERROR [storageadmin.middleware:33] Exception while running command(['sss', 'subvolume', 'list', '-s', '0']): [Errno 2] No such file or directory
Traceback (most recent call last):
  File "/opt/rockstor/eggs/Django-1.8.16-py2.7.egg/django/core/handlers/base.py", line 132, in get_response
    response = wrapped_callback(request, *callback_args, **callback_kwargs)
  File "/opt/rockstor/eggs/Django-1.8.16-py2.7.egg/django/views/decorators/csrf.py", line 58, in wrapped_view
    return view_func(*args, **kwargs)
  File "/opt/rockstor/eggs/Django-1.8.16-py2.7.egg/django/views/generic/base.py", line 71, in view
    return self.dispatch(request, *args, **kwargs)
  File "/opt/rockstor/eggs/djangorestframework-3.1.1-py2.7.egg/rest_framework/views.py", line 452, in dispatch
    response = self.handle_exception(exc)
  File "/opt/rockstor/eggs/djangorestframework-3.1.1-py2.7.egg/rest_framework/views.py", line 449, in dispatch
    response = handler(request, *args, **kwargs)
  File "/opt/rockstor/eggs/Django-1.8.16-py2.7.egg/django/utils/decorators.py", line 145, in inner
    return func(*args, **kwargs)
  File "/opt/rockstor/src/rockstor/storageadmin/views/command.py", line 345, in post
    import_shares(p, request)
  File "/opt/rockstor/src/rockstor/storageadmin/views/share_helpers.py", line 86, in import_shares
    shares_in_pool = shares_info(pool)
  File "/opt/rockstor/src/rockstor/fs/btrfs.py", line 650, in shares_info
    snap_idmap = snapshot_idmap(pool_mnt_pt)
  File "/opt/rockstor/src/rockstor/fs/btrfs.py", line 618, in snapshot_idmap
    out, e, rc = run_command([BTRFS, 'subvolume', 'list', '-s', pool_mnt_pt])
  File "/opt/rockstor/src/rockstor/system/osi.py", line 113, in run_command
    'Exception while running command({}): {}'.format(cmd, e))
Exception: Exception while running command(['sss', 'subvolume', 'list', '-s', '0']): [Errno 2] No such file or directory
[23/Aug/2019 14:22:50] ERROR [storageadmin.middleware:32] Exception occurred while processing a request. Path: /api/commands/refresh-snapshot-state method: POST
[23/Aug/2019 14:22:50] ERROR [storageadmin.middleware:33] Exception while running command(['sss', 'subvolume', 'list', '-u', '-p', '-q', '/po']): [Errno 2] No such file or directory
Traceback (most recent call last):
  File "/opt/rockstor/eggs/Django-1.8.16-py2.7.egg/django/core/handlers/base.py", line 132, in get_response
    response = wrapped_callback(request, *callback_args, **callback_kwargs)
  File "/opt/rockstor/eggs/Django-1.8.16-py2.7.egg/django/views/decorators/csrf.py", line 58, in wrapped_view
    return view_func(*args, **kwargs)
  File "/opt/rockstor/eggs/Django-1.8.16-py2.7.egg/django/views/generic/base.py", line 71, in view
    return self.dispatch(request, *args, **kwargs)
  File "/opt/rockstor/eggs/djangorestframework-3.1.1-py2.7.egg/rest_framework/views.py", line 452, in dispatch
    response = self.handle_exception(exc)
  File "/opt/rockstor/eggs/djangorestframework-3.1.1-py2.7.egg/rest_framework/views.py", line 449, in dispatch
    response = handler(request, *args, **kwargs)
  File "/opt/rockstor/eggs/Django-1.8.16-py2.7.egg/django/utils/decorators.py", line 145, in inner
    return func(*args, **kwargs)
  File "/opt/rockstor/src/rockstor/storageadmin/views/command.py", line 350, in post
    import_snapshots(share)
  File "/opt/rockstor/src/rockstor/storageadmin/views/share_helpers.py", line 209, in import_snapshots
    share.name)
  File "/opt/rockstor/src/rockstor/fs/btrfs.py", line 749, in snaps_info
    pool_mnt_pt])
  File "/opt/rockstor/src/rockstor/system/osi.py", line 113, in run_command
    'Exception while running command({}): {}'.format(cmd, e))
Exception: Exception while running command(['sss', 'subvolume', 'list', '-u', '-p', '-q', '/po']): [Errno 2] No such file or directory
[23/Aug/2019 14:24:51] ERROR [storageadmin.util:44] Exception: unsupported operand type(s) for +: 'NoneType' and 'str'
Traceback (most recent call last):
  File "/opt/rockstor/src/rockstor/rest_framework_custom/generic_view.py", line 41, in _handle_exception
    yield
  File "/opt/rockstor/src/rockstor/storageadmin/views/disk.py", line 416, in post
    return self._update_disk_state()
  File "/opt/rockstor/eggs/Django-1.8.16-py2.7.egg/django/utils/decorators.py", line 145, in inner
    return func(*args, **kwargs)
  File "/opt/rockstor/src/rockstor/storageadmin/views/disk.py", line 75, in _update_disk_state
    disks = scan_disks(settings.MIN_DISK_SIZE)
  File "/opt/rockstor/src/rockstor/system/osi.py", line 380, in scan_disks
    part_regex = base_root_disk + '\d+'
TypeError: unsupported operand type(s) for +: 'NoneType' and 'str'
[23/Aug/2019 14:24:51] DEBUG [storageadmin.util:45] Current Rockstor version: Unknown Version
[23/Aug/2019 14:24:51] ERROR [storageadmin.views.command:99] Exception while refreshing state for Pool(po). Moving on: Exception while running command(['sss', 'fi', 'show', '/dev/disk/by-id/wwn-0x6000c291b069fa5b74bc17fa8ebcf907']): [Errno 2] No such file or directory
[23/Aug/2019 14:24:51] ERROR [storageadmin.views.command:100] Exception while running command(['sss', 'fi', 'show', '/dev/disk/by-id/wwn-0x6000c291b069fa5b74bc17fa8ebcf907']): [Errno 2] No such file or directory
Traceback (most recent call last):
  File "/opt/rockstor/src/rockstor/storageadmin/views/command.py", line 80, in _refresh_pool_state
    is_root_pool)
  File "/opt/rockstor/src/rockstor/fs/btrfs.py", line 260, in get_pool_info
    o, e, rc = run_command(cmd)
  File "/opt/rockstor/src/rockstor/system/osi.py", line 113, in run_command
    'Exception while running command({}): {}'.format(cmd, e))
Exception: Exception while running command(['sss', 'fi', 'show', '/dev/disk/by-id/wwn-0x6000c291b069fa5b74bc17fa8ebcf907']): [Errno 2] No such file or directory
[23/Aug/2019 14:24:51] ERROR [storageadmin.middleware:32] Exception occurred while processing a request. Path: /api/commands/refresh-share-state method: POST
[23/Aug/2019 14:24:51] ERROR [storageadmin.middleware:33] Exception while running command(['sss', 'subvolume', 'list', '-s', '0']): [Errno 2] No such file or directory
Traceback (most recent call last):
  File "/opt/rockstor/eggs/Django-1.8.16-py2.7.egg/django/core/handlers/base.py", line 132, in get_response
    response = wrapped_callback(request, *callback_args, **callback_kwargs)
  File "/opt/rockstor/eggs/Django-1.8.16-py2.7.egg/django/views/decorators/csrf.py", line 58, in wrapped_view
    return view_func(*args, **kwargs)
  File "/opt/rockstor/eggs/Django-1.8.16-py2.7.egg/django/views/generic/base.py", line 71, in view
    return self.dispatch(request, *args, **kwargs)
  File "/opt/rockstor/eggs/djangorestframework-3.1.1-py2.7.egg/rest_framework/views.py", line 452, in dispatch
    response = self.handle_exception(exc)
  File "/opt/rockstor/eggs/djangorestframework-3.1.1-py2.7.egg/rest_framework/views.py", line 449, in dispatch
    response = handler(request, *args, **kwargs)
  File "/opt/rockstor/eggs/Django-1.8.16-py2.7.egg/django/utils/decorators.py", line 145, in inner
    return func(*args, **kwargs)
  File "/opt/rockstor/src/rockstor/storageadmin/views/command.py", line 345, in post
    import_shares(p, request)
  File "/opt/rockstor/src/rockstor/storageadmin/views/share_helpers.py", line 86, in import_shares
    shares_in_pool = shares_info(pool)
  File "/opt/rockstor/src/rockstor/fs/btrfs.py", line 650, in shares_info
    snap_idmap = snapshot_idmap(pool_mnt_pt)
  File "/opt/rockstor/src/rockstor/fs/btrfs.py", line 618, in snapshot_idmap
    out, e, rc = run_command([BTRFS, 'subvolume', 'list', '-s', pool_mnt_pt])
  File "/opt/rockstor/src/rockstor/system/osi.py", line 113, in run_command
    'Exception while running command({}): {}'.format(cmd, e))
Exception: Exception while running command(['sss', 'subvolume', 'list', '-s', '0']): [Errno 2] No such file or directory
[23/Aug/2019 14:24:51] ERROR [storageadmin.middleware:32] Exception occurred while processing a request. Path: /api/commands/refresh-snapshot-state method: POST
[23/Aug/2019 14:24:51] ERROR [storageadmin.middleware:33] Exception while running command(['sss', 'subvolume', 'list', '-u', '-p', '-q', '/po']): [Errno 2] No such file or directory
Traceback (most recent call last):
  File "/opt/rockstor/eggs/Django-1.8.16-py2.7.egg/django/core/handlers/base.py", line 132, in get_response
    response = wrapped_callback(request, *callback_args, **callback_kwargs)
  File "/opt/rockstor/eggs/Django-1.8.16-py2.7.egg/django/views/decorators/csrf.py", line 58, in wrapped_view
    return view_func(*args, **kwargs)
  File "/opt/rockstor/eggs/Django-1.8.16-py2.7.egg/django/views/generic/base.py", line 71, in view
    return self.dispatch(request, *args, **kwargs)
  File "/opt/rockstor/eggs/djangorestframework-3.1.1-py2.7.egg/rest_framework/views.py", line 452, in dispatch
    response = self.handle_exception(exc)
  File "/opt/rockstor/eggs/djangorestframework-3.1.1-py2.7.egg/rest_framework/views.py", line 449, in dispatch
    response = handler(request, *args, **kwargs)
  File "/opt/rockstor/eggs/Django-1.8.16-py2.7.egg/django/utils/decorators.py", line 145, in inner
    return func(*args, **kwargs)
  File "/opt/rockstor/src/rockstor/storageadmin/views/command.py", line 350, in post
    import_snapshots(share)
  File "/opt/rockstor/src/rockstor/storageadmin/views/share_helpers.py", line 209, in import_snapshots
    share.name)
  File "/opt/rockstor/src/rockstor/fs/btrfs.py", line 749, in snaps_info
    pool_mnt_pt])
  File "/opt/rockstor/src/rockstor/system/osi.py", line 113, in run_command
    'Exception while running command({}): {}'.format(cmd, e))
Exception: Exception while running command(['sss', 'subvolume', 'list', '-u', '-p', '-q', '/po']): [Errno 2] No such file or directory
[23/Aug/2019 14:26:51] ERROR [storageadmin.util:44] Exception: unsupported operand type(s) for +: 'NoneType' and 'str'
Traceback (most recent call last):
  File "/opt/rockstor/src/rockstor/rest_framework_custom/generic_view.py", line 41, in _handle_exception
    yield
  File "/opt/rockstor/src/rockstor/storageadmin/views/disk.py", line 416, in post
    return self._update_disk_state()
  File "/opt/rockstor/eggs/Django-1.8.16-py2.7.egg/django/utils/decorators.py", line 145, in inner
    return func(*args, **kwargs)
  File "/opt/rockstor/src/rockstor/storageadmin/views/disk.py", line 75, in _update_disk_state
    disks = scan_disks(settings.MIN_DISK_SIZE)
  File "/opt/rockstor/src/rockstor/system/osi.py", line 380, in scan_disks
    part_regex = base_root_disk + '\d+'
TypeError: unsupported operand type(s) for +: 'NoneType' and 'str'
[23/Aug/2019 14:26:51] DEBUG [storageadmin.util:45] Current Rockstor version: Unknown Version
[23/Aug/2019 14:26:52] ERROR [storageadmin.views.command:99] Exception while refreshing state for Pool(po). Moving on: Exception while running command(['sss', 'fi', 'show', '/dev/disk/by-id/wwn-0x6000c291b069fa5b74bc17fa8ebcf907']): [Errno 2] No such file or directory
[23/Aug/2019 14:26:52] ERROR [storageadmin.views.command:100] Exception while running command(['sss', 'fi', 'show', '/dev/disk/by-id/wwn-0x6000c291b069fa5b74bc17fa8ebcf907']): [Errno 2] No such file or directory
Traceback (most recent call last):
  File "/opt/rockstor/src/rockstor/storageadmin/views/command.py", line 80, in _refresh_pool_state
    is_root_pool)
  File "/opt/rockstor/src/rockstor/fs/btrfs.py", line 260, in get_pool_info
    o, e, rc = run_command(cmd)
  File "/opt/rockstor/src/rockstor/system/osi.py", line 113, in run_command
    'Exception while running command({}): {}'.format(cmd, e))
Exception: Exception while running command(['sss', 'fi', 'show', '/dev/disk/by-id/wwn-0x6000c291b069fa5b74bc17fa8ebcf907']): [Errno 2] No such file or directory
[23/Aug/2019 14:26:52] ERROR [storageadmin.middleware:32] Exception occurred while processing a request. Path: /api/commands/refresh-share-state method: POST
[23/Aug/2019 14:26:52] ERROR [storageadmin.middleware:33] Exception while running command(['sss', 'subvolume', 'list', '-s', '0']): [Errno 2] No such file or directory
Traceback (most recent call last):
  File "/opt/rockstor/eggs/Django-1.8.16-py2.7.egg/django/core/handlers/base.py", line 132, in get_response
    response = wrapped_callback(request, *callback_args, **callback_kwargs)
  File "/opt/rockstor/eggs/Django-1.8.16-py2.7.egg/django/views/decorators/csrf.py", line 58, in wrapped_view
    return view_func(*args, **kwargs)
  File "/opt/rockstor/eggs/Django-1.8.16-py2.7.egg/django/views/generic/base.py", line 71, in view
    return self.dispatch(request, *args, **kwargs)
  File "/opt/rockstor/eggs/djangorestframework-3.1.1-py2.7.egg/rest_framework/views.py", line 452, in dispatch
    response = self.handle_exception(exc)
  File "/opt/rockstor/eggs/djangorestframework-3.1.1-py2.7.egg/rest_framework/views.py", line 449, in dispatch
    response = handler(request, *args, **kwargs)
  File "/opt/rockstor/eggs/Django-1.8.16-py2.7.egg/django/utils/decorators.py", line 145, in inner
    return func(*args, **kwargs)
  File "/opt/rockstor/src/rockstor/storageadmin/views/command.py", line 345, in post
    import_shares(p, request)
  File "/opt/rockstor/src/rockstor/storageadmin/views/share_helpers.py", line 86, in import_shares
    shares_in_pool = shares_info(pool)
  File "/opt/rockstor/src/rockstor/fs/btrfs.py", line 650, in shares_info
    snap_idmap = snapshot_idmap(pool_mnt_pt)
  File "/opt/rockstor/src/rockstor/fs/btrfs.py", line 618, in snapshot_idmap
    out, e, rc = run_command([BTRFS, 'subvolume', 'list', '-s', pool_mnt_pt])
  File "/opt/rockstor/src/rockstor/system/osi.py", line 113, in run_command
    'Exception while running command({}): {}'.format(cmd, e))
Exception: Exception while running command(['sss', 'subvolume', 'list', '-s', '0']): [Errno 2] No such file or directory
[23/Aug/2019 14:26:52] ERROR [storageadmin.middleware:32] Exception occurred while processing a request. Path: /api/commands/refresh-snapshot-state method: POST
[23/Aug/2019 14:26:52] ERROR [storageadmin.middleware:33] Exception while running command(['sss', 'subvolume', 'list', '-u', '-p', '-q', '/po']): [Errno 2] No such file or directory
Traceback (most recent call last):
  File "/opt/rockstor/eggs/Django-1.8.16-py2.7.egg/django/core/handlers/base.py", line 132, in get_response
    response = wrapped_callback(request, *callback_args, **callback_kwargs)
  File "/opt/rockstor/eggs/Django-1.8.16-py2.7.egg/django/views/decorators/csrf.py", line 58, in wrapped_view
    return view_func(*args, **kwargs)
  File "/opt/rockstor/eggs/Django-1.8.16-py2.7.egg/django/views/generic/base.py", line 71, in view
    return self.dispatch(request, *args, **kwargs)
  File "/opt/rockstor/eggs/djangorestframework-3.1.1-py2.7.egg/rest_framework/views.py", line 452, in dispatch
    response = self.handle_exception(exc)
  File "/opt/rockstor/eggs/djangorestframework-3.1.1-py2.7.egg/rest_framework/views.py", line 449, in dispatch
    response = handler(request, *args, **kwargs)
  File "/opt/rockstor/eggs/Django-1.8.16-py2.7.egg/django/utils/decorators.py", line 145, in inner
    return func(*args, **kwargs)
  File "/opt/rockstor/src/rockstor/storageadmin/views/command.py", line 350, in post
    import_snapshots(share)
  File "/opt/rockstor/src/rockstor/storageadmin/views/share_helpers.py", line 209, in import_snapshots
    share.name)
  File "/opt/rockstor/src/rockstor/fs/btrfs.py", line 749, in snaps_info
    pool_mnt_pt])
  File "/opt/rockstor/src/rockstor/system/osi.py", line 113, in run_command
    'Exception while running command({}): {}'.format(cmd, e))
Exception: Exception while running command(['sss', 'subvolume', 'list', '-u', '-p', '-q', '/po']): [Errno 2] No such file or directory
[23/Aug/2019 14:28:52] ERROR [storageadmin.util:44] Exception: unsupported operand type(s) for +: 'NoneType' and 'str'
Traceback (most recent call last):
  File "/opt/rockstor/src/rockstor/rest_framework_custom/generic_view.py", line 41, in _handle_exception
    yield
  File "/opt/rockstor/src/rockstor/storageadmin/views/disk.py", line 416, in post
    return self._update_disk_state()
  File "/opt/rockstor/eggs/Django-1.8.16-py2.7.egg/django/utils/decorators.py", line 145, in inner
    return func(*args, **kwargs)
  File "/opt/rockstor/src/rockstor/storageadmin/views/disk.py", line 75, in _update_disk_state
    disks = scan_disks(settings.MIN_DISK_SIZE)
  File "/opt/rockstor/src/rockstor/system/osi.py", line 380, in scan_disks
    part_regex = base_root_disk + '\d+'
TypeError: unsupported operand type(s) for +: 'NoneType' and 'str'
[23/Aug/2019 14:28:52] DEBUG [storageadmin.util:45] Current Rockstor version: Unknown Version
[23/Aug/2019 14:28:52] ERROR [storageadmin.views.command:99] Exception while refreshing state for Pool(po). Moving on: Exception while running command(['sss', 'fi', 'show', '/dev/disk/by-id/wwn-0x6000c291b069fa5b74bc17fa8ebcf907']): [Errno 2] No such file or directory
[23/Aug/2019 14:28:52] ERROR [storageadmin.views.command:100] Exception while running command(['sss', 'fi', 'show', '/dev/disk/by-id/wwn-0x6000c291b069fa5b74bc17fa8ebcf907']): [Errno 2] No such file or directory
Traceback (most recent call last):
  File "/opt/rockstor/src/rockstor/storageadmin/views/command.py", line 80, in _refresh_pool_state
    is_root_pool)
  File "/opt/rockstor/src/rockstor/fs/btrfs.py", line 260, in get_pool_info
    o, e, rc = run_command(cmd)
  File "/opt/rockstor/src/rockstor/system/osi.py", line 113, in run_command
    'Exception while running command({}): {}'.format(cmd, e))
Exception: Exception while running command(['sss', 'fi', 'show', '/dev/disk/by-id/wwn-0x6000c291b069fa5b74bc17fa8ebcf907']): [Errno 2] No such file or directory
[23/Aug/2019 14:28:52] ERROR [storageadmin.middleware:32] Exception occurred while processing a request. Path: /api/commands/refresh-share-state method: POST
[23/Aug/2019 14:28:52] ERROR [storageadmin.middleware:33] Exception while running command(['sss', 'subvolume', 'list', '-s', '0']): [Errno 2] No such file or directory
Traceback (most recent call last):
  File "/opt/rockstor/eggs/Django-1.8.16-py2.7.egg/django/core/handlers/base.py", line 132, in get_response
    response = wrapped_callback(request, *callback_args, **callback_kwargs)
  File "/opt/rockstor/eggs/Django-1.8.16-py2.7.egg/django/views/decorators/csrf.py", line 58, in wrapped_view
    return view_func(*args, **kwargs)
  File "/opt/rockstor/eggs/Django-1.8.16-py2.7.egg/django/views/generic/base.py", line 71, in view
    return self.dispatch(request, *args, **kwargs)
  File "/opt/rockstor/eggs/djangorestframework-3.1.1-py2.7.egg/rest_framework/views.py", line 452, in dispatch
    response = self.handle_exception(exc)
  File "/opt/rockstor/eggs/djangorestframework-3.1.1-py2.7.egg/rest_framework/views.py", line 449, in dispatch
    response = handler(request, *args, **kwargs)
  File "/opt/rockstor/eggs/Django-1.8.16-py2.7.egg/django/utils/decorators.py", line 145, in inner
    return func(*args, **kwargs)
  File "/opt/rockstor/src/rockstor/storageadmin/views/command.py", line 345, in post
    import_shares(p, request)
  File "/opt/rockstor/src/rockstor/storageadmin/views/share_helpers.py", line 86, in import_shares
    shares_in_pool = shares_info(pool)
  File "/opt/rockstor/src/rockstor/fs/btrfs.py", line 650, in shares_info
    snap_idmap = snapshot_idmap(pool_mnt_pt)
  File "/opt/rockstor/src/rockstor/fs/btrfs.py", line 618, in snapshot_idmap
    out, e, rc = run_command([BTRFS, 'subvolume', 'list', '-s', pool_mnt_pt])
  File "/opt/rockstor/src/rockstor/system/osi.py", line 113, in run_command
    'Exception while running command({}): {}'.format(cmd, e))
Exception: Exception while running command(['sss', 'subvolume', 'list', '-s', '0']): [Errno 2] No such file or directory
[23/Aug/2019 14:28:52] ERROR [storageadmin.middleware:32] Exception occurred while processing a request. Path: /api/commands/refresh-snapshot-state method: POST
[23/Aug/2019 14:28:52] ERROR [storageadmin.middleware:33] Exception while running command(['sss', 'subvolume', 'list', '-u', '-p', '-q', '/po']): [Errno 2] No such file or directory
Traceback (most recent call last):
  File "/opt/rockstor/eggs/Django-1.8.16-py2.7.egg/django/core/handlers/base.py", line 132, in get_response
    response = wrapped_callback(request, *callback_args, **callback_kwargs)
  File "/opt/rockstor/eggs/Django-1.8.16-py2.7.egg/django/views/decorators/csrf.py", line 58, in wrapped_view
    return view_func(*args, **kwargs)
  File "/opt/rockstor/eggs/Django-1.8.16-py2.7.egg/django/views/generic/base.py", line 71, in view
    return self.dispatch(request, *args, **kwargs)
  File "/opt/rockstor/eggs/djangorestframework-3.1.1-py2.7.egg/rest_framework/views.py", line 452, in dispatch
    response = self.handle_exception(exc)
  File "/opt/rockstor/eggs/djangorestframework-3.1.1-py2.7.egg/rest_framework/views.py", line 449, in dispatch
    response = handler(request, *args, **kwargs)
  File "/opt/rockstor/eggs/Django-1.8.16-py2.7.egg/django/utils/decorators.py", line 145, in inner
    return func(*args, **kwargs)
  File "/opt/rockstor/src/rockstor/storageadmin/views/command.py", line 350, in post
    import_snapshots(share)
  File "/opt/rockstor/src/rockstor/storageadmin/views/share_helpers.py", line 209, in import_snapshots
    share.name)
  File "/opt/rockstor/src/rockstor/fs/btrfs.py", line 749, in snaps_info
    pool_mnt_pt])
  File "/opt/rockstor/src/rockstor/system/osi.py", line 113, in run_command
    'Exception while running command({}): {}'.format(cmd, e))
Exception: Exception while running command(['sss', 'subvolume', 'list', '-u', '-p', '-q', '/po']): [Errno 2] No such file or directory
